Microsoft Windows [Version 10.0.19041.508]
(c) 2020 Microsoft Corporation. All rights reserved.

C:\Users\wildc>cd C:\Users\wildc\Documents\GitHub\ShieldBot

C:\Users\wildc\Documents\GitHub\ShieldBot>bot.py
C:\Users\wildc\Documents\GitHub\ShieldBot
-----
Traceback (most recent call last):
  File "C:\Users\wildc\Documents\GitHub\ShieldBot\bot.py", line 71, in <module>
    for file in os.listdir(cwd+"/cogs"):
NameError: name 'os' is not defined

C:\Users\wildc\Documents\GitHub\ShieldBot>bot.py
C:\Users\wildc\Documents\GitHub\ShieldBot
-----
Traceback (most recent call last):
  File "C:\Users\wildc\AppData\Local\Programs\Python\Python38-32\lib\site-packages\discord\ext\commands\bot.py", line 607, in _load_from_module_spec
    spec.loader.exec_module(lib)
  File "<frozen importlib._bootstrap_external>", line 779, in exec_module
  File "<frozen importlib._bootstrap_external>", line 916, in get_code
  File "<frozen importlib._bootstrap_external>", line 846, in source_to_code
  File "<frozen importlib._bootstrap>", line 219, in _call_with_frames_removed
  File "C:\Users\wildc\Documents\GitHub\ShieldBot\cogs\commands.py", line 51
    """"
       ^
SyntaxError: EOL while scanning string literal

The above exception was the direct cause of the following exception:

Traceback (most recent call last):
  File "C:\Users\wildc\Documents\GitHub\ShieldBot\bot.py", line 75, in <module>
    client.load_extension(f"cogs.{file[:-3]}")
  File "C:\Users\wildc\AppData\Local\Programs\Python\Python38-32\lib\site-packages\discord\ext\commands\bot.py", line 664, in load_extension
    self._load_from_module_spec(spec, name)
  File "C:\Users\wildc\AppData\Local\Programs\Python\Python38-32\lib\site-packages\discord\ext\commands\bot.py", line 610, in _load_from_module_spec
    raise errors.ExtensionFailed(key, e) from e
discord.ext.commands.errors.ExtensionFailed: Extension 'cogs.commands' raised an error: SyntaxError: EOL while scanning string literal (commands.py, line 51)

C:\Users\wildc\Documents\GitHub\ShieldBot>bot.py
C:\Users\wildc\Documents\GitHub\ShieldBot
-----
Traceback (most recent call last):
  File "C:\Users\wildc\AppData\Local\Programs\Python\Python38-32\lib\site-packages\discord\ext\commands\bot.py", line 607, in _load_from_module_spec
    spec.loader.exec_module(lib)
  File "<frozen importlib._bootstrap_external>", line 779, in exec_module
  File "<frozen importlib._bootstrap_external>", line 916, in get_code
  File "<frozen importlib._bootstrap_external>", line 846, in source_to_code
  File "<frozen importlib._bootstrap>", line 219, in _call_with_frames_removed
  File "C:\Users\wildc\Documents\GitHub\ShieldBot\cogs\events.py", line 10
    def __init__(self.client, client):
                     ^
SyntaxError: invalid syntax

The above exception was the direct cause of the following exception:

Traceback (most recent call last):
  File "C:\Users\wildc\Documents\GitHub\ShieldBot\bot.py", line 75, in <module>
    client.load_extension(f"cogs.{file[:-3]}")
  File "C:\Users\wildc\AppData\Local\Programs\Python\Python38-32\lib\site-packages\discord\ext\commands\bot.py", line 664, in load_extension
    self._load_from_module_spec(spec, name)
  File "C:\Users\wildc\AppData\Local\Programs\Python\Python38-32\lib\site-packages\discord\ext\commands\bot.py", line 610, in _load_from_module_spec
    raise errors.ExtensionFailed(key, e) from e
discord.ext.commands.errors.ExtensionFailed: Extension 'cogs.events' raised an error: SyntaxError: invalid syntax (events.py, line 10)

C:\Users\wildc\Documents\GitHub\ShieldBot>bot.py
C:\Users\wildc\Documents\GitHub\ShieldBot
-----
Traceback (most recent call last):
  File "C:\Users\wildc\AppData\Local\Programs\Python\Python38-32\lib\site-packages\discord\ext\commands\bot.py", line 607, in _load_from_module_spec
    spec.loader.exec_module(lib)
  File "<frozen importlib._bootstrap_external>", line 783, in exec_module
  File "<frozen importlib._bootstrap>", line 219, in _call_with_frames_removed
  File "C:\Users\wildc\Documents\GitHub\ShieldBot\cogs\events.py", line 8, in <module>
    class Events(commands.Cog):
  File "C:\Users\wildc\Documents\GitHub\ShieldBot\cogs\events.py", line 29, in Events
    @command.Cog.listener()
NameError: name 'command' is not defined

The above exception was the direct cause of the following exception:

Traceback (most recent call last):
  File "C:\Users\wildc\Documents\GitHub\ShieldBot\bot.py", line 75, in <module>
    client.load_extension(f"cogs.{file[:-3]}")
  File "C:\Users\wildc\AppData\Local\Programs\Python\Python38-32\lib\site-packages\discord\ext\commands\bot.py", line 664, in load_extension
    self._load_from_module_spec(spec, name)
  File "C:\Users\wildc\AppData\Local\Programs\Python\Python38-32\lib\site-packages\discord\ext\commands\bot.py", line 610, in _load_from_module_spec
    raise errors.ExtensionFailed(key, e) from e
discord.ext.commands.errors.ExtensionFailed: Extension 'cogs.events' raised an error: NameError: name 'command' is not defined

C:\Users\wildc\Documents\GitHub\ShieldBot>bot.py
C:\Users\wildc\Documents\GitHub\ShieldBot
-----
INFO:discord.client:logging in using static token
INFO:discord.gateway:Shard ID None has sent the IDENTIFY payload.
INFO:discord.gateway:Shard ID None has connected to Gateway: ["gateway-prd-main-w1pf",{"micros":49463,"calls":["discord-sessions-prd-2-49",{"micros":48644,"calls":["start_session",{"micros":30128,"calls":["api-prd-main-m83m",{"micros":28082,"calls":["get_user",{"micros":3373},"add_authorized_ip",{"micros":1426},"get_guilds",{"micros":4353},"coros_wait",{"micros":0}]}]},"guilds_connect",{"micros":5,"calls":[]},"presence_connect",{"micros":17112,"calls":[]}]}]}] (Session ID: ae6664f8cc24fc212d8ec5b7acc0497b).
-----
Logged in as: ShieldBot <@754876371829784717>
-----
My current prefix is: .
-----
Ignoring exception in on_ready
Traceback (most recent call last):
  File "C:\Users\wildc\AppData\Local\Programs\Python\Python38-32\lib\site-packages\discord\client.py", line 312, in _run_event
    await coro(*args, **kwargs)
  File "C:\Users\wildc\Documents\GitHub\ShieldBot\bot.py", line 51, in on_ready
    data = read_json("blacklist")
NameError: name 'read_json' is not defined
Commands Cog had been loaded
-----
Events Cog had been loaded
-----
INFO:discord.client:Received signal to terminate bot and event loop.
INFO:discord.client:Cleaning up tasks.
INFO:discord.client:Cleaning up after 1 tasks.
INFO:discord.client:All tasks finished cancelling.
INFO:discord.client:Closing the event loop.

C:\Users\wildc\Documents\GitHub\ShieldBot>bot.py
C:\Users\wildc\Documents\GitHub\ShieldBot
-----
INFO:discord.client:logging in using static token
INFO:discord.gateway:Shard ID None has sent the IDENTIFY payload.
INFO:discord.gateway:Shard ID None has connected to Gateway: ["gateway-prd-main-37nw",{"micros":100033,"calls":["discord-sessions-prd-1-10",{"micros":98959,"calls":["start_session",{"micros":74020,"calls":["api-prd-main-hc8l",{"micros":69941,"calls":["get_user",{"micros":5307},"add_authorized_ip",{"micros":2485},"get_guilds",{"micros":11281},"coros_wait",{"micros":2}]}]},"guilds_connect",{"micros":16,"calls":[]},"presence_connect",{"micros":22459,"calls":[]}]}]}] (Session ID: cae8e4900292410fbbb0c27e96d8e961).
-----
Logged in as: ShieldBot <@754876371829784717>
-----
My current prefix is: .
-----
Commands Cog had been loaded
-----
Events Cog had been loaded
-----
Ignoring exception in on_message
Traceback (most recent call last):
  File "C:\Users\wildc\AppData\Local\Programs\Python\Python38-32\lib\site-packages\discord\ext\commands\core.py", line 683, in _parse_arguments
    next(iterator)
StopIteration

During handling of the above exception, another exception occurred:

Traceback (most recent call last):
  File "C:\Users\wildc\AppData\Local\Programs\Python\Python38-32\lib\site-packages\discord\client.py", line 312, in _run_event
    await coro(*args, **kwargs)
  File "C:\Users\wildc\Documents\GitHub\ShieldBot\bot.py", line 66, in on_message
    await client.process_commands(message)
  File "C:\Users\wildc\AppData\Local\Programs\Python\Python38-32\lib\site-packages\discord\ext\commands\bot.py", line 940, in process_commands
    await self.invoke(ctx)
  File "C:\Users\wildc\AppData\Local\Programs\Python\Python38-32\lib\site-packages\discord\ext\commands\bot.py", line 903, in invoke
    await ctx.command.invoke(ctx)
  File "C:\Users\wildc\AppData\Local\Programs\Python\Python38-32\lib\site-packages\discord\ext\commands\core.py", line 847, in invoke
    await self.prepare(ctx)
  File "C:\Users\wildc\AppData\Local\Programs\Python\Python38-32\lib\site-packages\discord\ext\commands\core.py", line 784, in prepare
    await self._parse_arguments(ctx)
  File "C:\Users\wildc\AppData\Local\Programs\Python\Python38-32\lib\site-packages\discord\ext\commands\core.py", line 686, in _parse_arguments
    raise discord.ClientException(fmt.format(self))
discord.errors.ClientException: Callback for hi command is missing "ctx" parameter.
Ignoring exception in on_message
Traceback (most recent call last):
  File "C:\Users\wildc\AppData\Local\Programs\Python\Python38-32\lib\site-packages\discord\ext\commands\core.py", line 683, in _parse_arguments
    next(iterator)
StopIteration

During handling of the above exception, another exception occurred:

Traceback (most recent call last):
  File "C:\Users\wildc\AppData\Local\Programs\Python\Python38-32\lib\site-packages\discord\client.py", line 312, in _run_event
    await coro(*args, **kwargs)
  File "C:\Users\wildc\Documents\GitHub\ShieldBot\bot.py", line 66, in on_message
    await client.process_commands(message)
  File "C:\Users\wildc\AppData\Local\Programs\Python\Python38-32\lib\site-packages\discord\ext\commands\bot.py", line 940, in process_commands
    await self.invoke(ctx)
  File "C:\Users\wildc\AppData\Local\Programs\Python\Python38-32\lib\site-packages\discord\ext\commands\bot.py", line 903, in invoke
    await ctx.command.invoke(ctx)
  File "C:\Users\wildc\AppData\Local\Programs\Python\Python38-32\lib\site-packages\discord\ext\commands\core.py", line 847, in invoke
    await self.prepare(ctx)
  File "C:\Users\wildc\AppData\Local\Programs\Python\Python38-32\lib\site-packages\discord\ext\commands\core.py", line 784, in prepare
    await self._parse_arguments(ctx)
  File "C:\Users\wildc\AppData\Local\Programs\Python\Python38-32\lib\site-packages\discord\ext\commands\core.py", line 686, in _parse_arguments
    raise discord.ClientException(fmt.format(self))
discord.errors.ClientException: Callback for hi command is missing "ctx" parameter.
INFO:discord.client:Received signal to terminate bot and event loop.
INFO:discord.client:Cleaning up tasks.
INFO:discord.client:Cleaning up after 1 tasks.
INFO:discord.client:All tasks finished cancelling.
INFO:discord.client:Closing the event loop.
Exception ignored in: <function _ProactorBasePipeTransport.__del__ at 0x0303CF10>
Traceback (most recent call last):
  File "C:\Users\wildc\AppData\Local\Programs\Python\Python38-32\lib\asyncio\proactor_events.py", line 116, in __del__
    self.close()
  File "C:\Users\wildc\AppData\Local\Programs\Python\Python38-32\lib\asyncio\proactor_events.py", line 108, in close
    self._loop.call_soon(self._call_connection_lost, None)
  File "C:\Users\wildc\AppData\Local\Programs\Python\Python38-32\lib\asyncio\base_events.py", line 719, in call_soon
    self._check_closed()
  File "C:\Users\wildc\AppData\Local\Programs\Python\Python38-32\lib\asyncio\base_events.py", line 508, in _check_closed
    raise RuntimeError('Event loop is closed')
RuntimeError: Event loop is closed

C:\Users\wildc\Documents\GitHub\ShieldBot>

C:\Users\wildc\Documents\GitHub\ShieldBot>bot.py
C:\Users\wildc\Documents\GitHub\ShieldBot
-----
INFO:discord.client:logging in using static token
INFO:discord.gateway:Shard ID None has sent the IDENTIFY payload.
INFO:discord.gateway:Shard ID None has connected to Gateway: ["gateway-prd-main-3mm3",{"micros":57551,"calls":["discord-sessions-prd-2-43",{"micros":54980,"calls":["start_session",{"micros":48532,"calls":["api-prd-main-mvc5",{"micros":46032,"calls":["get_user",{"micros":5324},"add_authorized_ip",{"micros":1290},"get_guilds",{"micros":5321},"coros_wait",{"micros":1}]}]},"guilds_connect",{"micros":28,"calls":[]},"presence_connect",{"micros":1,"calls":[]}]}]}] (Session ID: 513b93a9d68075aaa606fcceba703606).
-----
Logged in as: ShieldBot <@754876371829784717>
-----
My current prefix is: .
-----
Commands Cog had been loaded
-----
Events Cog had been loaded
-----
Ignoring exception in on_command_error
Traceback (most recent call last):
  File "C:\Users\wildc\AppData\Local\Programs\Python\Python38-32\lib\site-packages\discord\ext\commands\core.py", line 85, in wrapped
    ret = await coro(*args, **kwargs)
  File "C:\Users\wildc\Documents\GitHub\ShieldBot\cogs\commands.py", line 76, in blacklist
    data = cogs._json.read_json("blacklist")
  File "C:\Users\wildc\Documents\GitHub\ShieldBot\cogs\_json.py", line 25, in read_json
    cwd = get_path()
  File "C:\Users\wildc\Documents\GitHub\ShieldBot\cogs\_json.py", line 11, in get_path
    cwd = Path(_file_).parents[1]
NameError: name '_file_' is not defined

The above exception was the direct cause of the following exception:

Traceback (most recent call last):
  File "C:\Users\wildc\AppData\Local\Programs\Python\Python38-32\lib\site-packages\discord\client.py", line 312, in _run_event
    await coro(*args, **kwargs)
  File "C:\Users\wildc\Documents\GitHub\ShieldBot\cogs\events.py", line 61, in on_command_error
    raise error
  File "C:\Users\wildc\AppData\Local\Programs\Python\Python38-32\lib\site-packages\discord\ext\commands\bot.py", line 903, in invoke
    await ctx.command.invoke(ctx)
  File "C:\Users\wildc\AppData\Local\Programs\Python\Python38-32\lib\site-packages\discord\ext\commands\core.py", line 855, in invoke
    await injected(*ctx.args, **ctx.kwargs)
  File "C:\Users\wildc\AppData\Local\Programs\Python\Python38-32\lib\site-packages\discord\ext\commands\core.py", line 94, in wrapped
    raise CommandInvokeError(exc) from exc
discord.ext.commands.errors.CommandInvokeError: Command raised an exception: NameError: name '_file_' is not defined
INFO:discord.client:Received signal to terminate bot and event loop.
INFO:discord.client:Cleaning up tasks.
INFO:discord.client:Cleaning up after 1 tasks.
INFO:discord.client:All tasks finished cancelling.
INFO:discord.client:Closing the event loop.

C:\Users\wildc\Documents\GitHub\ShieldBot>bot.py
C:\Users\wildc\Documents\GitHub\ShieldBot
-----
INFO:discord.client:logging in using static token
INFO:discord.gateway:Shard ID None has sent the IDENTIFY payload.
INFO:discord.gateway:Shard ID None has connected to Gateway: ["gateway-prd-main-z971",{"micros":151689,"calls":["discord-sessions-prd-1-27",{"micros":146251,"calls":["start_session",{"micros":61938,"calls":["api-prd-main-2p8t",{"micros":59327,"calls":["get_user",{"micros":2685},"add_authorized_ip",{"micros":2452},"get_guilds",{"micros":3429},"coros_wait",{"micros":0}]}]},"guilds_connect",{"micros":27,"calls":[]},"presence_connect",{"micros":52138,"calls":[]}]}]}] (Session ID: 7e7331fbfcaf1092926dcb5023a664e4).
-----
Logged in as: ShieldBot <@754876371829784717>
-----
My current prefix is: .
-----
Commands Cog had been loaded
-----
Events Cog had been loaded
-----
Ignoring exception in on_command_error
Traceback (most recent call last):
  File "C:\Users\wildc\AppData\Local\Programs\Python\Python38-32\lib\site-packages\discord\ext\commands\core.py", line 85, in wrapped
    ret = await coro(*args, **kwargs)
  File "C:\Users\wildc\Documents\GitHub\ShieldBot\cogs\commands.py", line 87, in unblacklist
    self.bot.blacklisted_users.remove(user.id)
AttributeError: 'Commands' object has no attribute 'bot'

The above exception was the direct cause of the following exception:

Traceback (most recent call last):
  File "C:\Users\wildc\AppData\Local\Programs\Python\Python38-32\lib\site-packages\discord\client.py", line 312, in _run_event
    await coro(*args, **kwargs)
  File "C:\Users\wildc\Documents\GitHub\ShieldBot\cogs\events.py", line 61, in on_command_error
    raise error
  File "C:\Users\wildc\AppData\Local\Programs\Python\Python38-32\lib\site-packages\discord\ext\commands\bot.py", line 903, in invoke
    await ctx.command.invoke(ctx)
  File "C:\Users\wildc\AppData\Local\Programs\Python\Python38-32\lib\site-packages\discord\ext\commands\core.py", line 855, in invoke
    await injected(*ctx.args, **ctx.kwargs)
  File "C:\Users\wildc\AppData\Local\Programs\Python\Python38-32\lib\site-packages\discord\ext\commands\core.py", line 94, in wrapped
    raise CommandInvokeError(exc) from exc
discord.ext.commands.errors.CommandInvokeError: Command raised an exception: AttributeError: 'Commands' object has no attribute 'bot'
INFO:discord.client:Received signal to terminate bot and event loop.
INFO:discord.client:Cleaning up tasks.
INFO:discord.client:Cleaning up after 1 tasks.
INFO:discord.client:All tasks finished cancelling.
INFO:discord.client:Closing the event loop.

C:\Users\wildc\Documents\GitHub\ShieldBot>bot.py
C:\Users\wildc\Documents\GitHub\ShieldBot
-----
INFO:discord.client:logging in using static token
INFO:discord.gateway:Shard ID None has sent the IDENTIFY payload.
INFO:discord.gateway:Shard ID None has connected to Gateway: ["gateway-prd-main-bcqb",{"micros":43416,"calls":["discord-sessions-prd-2-39",{"micros":42191,"calls":["start_session",{"micros":26381,"calls":["api-prd-main-p0j5",{"micros":24347,"calls":["get_user",{"micros":2646},"add_authorized_ip",{"micros":1371},"get_guilds",{"micros":1269},"coros_wait",{"micros":1}]}]},"guilds_connect",{"micros":5,"calls":[]},"presence_connect",{"micros":13264,"calls":[]}]}]}] (Session ID: 25e909881b4a4ac0fbd657588cd9fcf4).
-----
Logged in as: ShieldBot <@754876371829784717>
-----
My current prefix is: .
-----
Commands Cog had been loaded
-----
Events Cog had been loaded
-----
Ignoring exception in on_command_error
Traceback (most recent call last):
  File "C:\Users\wildc\AppData\Local\Programs\Python\Python38-32\lib\site-packages\discord\ext\commands\core.py", line 85, in wrapped
    ret = await coro(*args, **kwargs)
  File "C:\Users\wildc\Documents\GitHub\ShieldBot\cogs\commands.py", line 87, in unblacklist
    self.client.blacklisted_users.remove(user.id)
ValueError: list.remove(x): x not in list

The above exception was the direct cause of the following exception:

Traceback (most recent call last):
  File "C:\Users\wildc\AppData\Local\Programs\Python\Python38-32\lib\site-packages\discord\client.py", line 312, in _run_event
    await coro(*args, **kwargs)
  File "C:\Users\wildc\Documents\GitHub\ShieldBot\cogs\events.py", line 61, in on_command_error
    raise error
  File "C:\Users\wildc\AppData\Local\Programs\Python\Python38-32\lib\site-packages\discord\ext\commands\bot.py", line 903, in invoke
    await ctx.command.invoke(ctx)
  File "C:\Users\wildc\AppData\Local\Programs\Python\Python38-32\lib\site-packages\discord\ext\commands\core.py", line 855, in invoke
    await injected(*ctx.args, **ctx.kwargs)
  File "C:\Users\wildc\AppData\Local\Programs\Python\Python38-32\lib\site-packages\discord\ext\commands\core.py", line 94, in wrapped
    raise CommandInvokeError(exc) from exc
discord.ext.commands.errors.CommandInvokeError: Command raised an exception: ValueError: list.remove(x): x not in list
INFO:discord.client:Received signal to terminate bot and event loop.
INFO:discord.client:Cleaning up tasks.
INFO:discord.client:Cleaning up after 1 tasks.
INFO:discord.client:All tasks finished cancelling.
INFO:discord.client:Closing the event loop.

C:\Users\wildc\Documents\GitHub\ShieldBot>bot.py
C:\Users\wildc\Documents\GitHub\ShieldBot
-----
INFO:discord.client:logging in using static token
INFO:discord.gateway:Shard ID None has sent the IDENTIFY payload.
INFO:discord.gateway:Shard ID None has connected to Gateway: ["gateway-prd-main-cc51",{"micros":148913,"calls":["discord-sessions-prd-1-31",{"micros":147911,"calls":["start_session",{"micros":122411,"calls":["api-prd-main-0scs",{"micros":120183,"calls":["get_user",{"micros":12077},"add_authorized_ip",{"micros":8313},"get_guilds",{"micros":18526},"coros_wait",{"micros":1}]}]},"guilds_connect",{"micros":10,"calls":[]},"presence_connect",{"micros":16209,"calls":[]}]}]}] (Session ID: 38c2570979588b90da846b259fa813fd).
-----
Logged in as: ShieldBot <@754876371829784717>
-----
My current prefix is: .
-----
Commands Cog had been loaded
-----
Events Cog had been loaded
-----
Ignoring exception in on_command_error
Traceback (most recent call last):
  File "C:\Users\wildc\AppData\Local\Programs\Python\Python38-32\lib\site-packages\discord\ext\commands\core.py", line 85, in wrapped
    ret = await coro(*args, **kwargs)
  File "C:\Users\wildc\Documents\GitHub\ShieldBot\cogs\commands.py", line 76, in blacklist
    data = cogs._json.read_json("blacklist")
  File "C:\Users\wildc\Documents\GitHub\ShieldBot\cogs\_json.py", line 25, in read_json
    cwd = get_path()
  File "C:\Users\wildc\Documents\GitHub\ShieldBot\cogs\_json.py", line 11, in get_path
    cwd = Path(_file_).parents[1]
NameError: name '_file_' is not defined

The above exception was the direct cause of the following exception:

Traceback (most recent call last):
  File "C:\Users\wildc\AppData\Local\Programs\Python\Python38-32\lib\site-packages\discord\client.py", line 312, in _run_event
    await coro(*args, **kwargs)
  File "C:\Users\wildc\Documents\GitHub\ShieldBot\cogs\events.py", line 61, in on_command_error
    raise error
  File "C:\Users\wildc\AppData\Local\Programs\Python\Python38-32\lib\site-packages\discord\ext\commands\bot.py", line 903, in invoke
    await ctx.command.invoke(ctx)
  File "C:\Users\wildc\AppData\Local\Programs\Python\Python38-32\lib\site-packages\discord\ext\commands\core.py", line 855, in invoke
    await injected(*ctx.args, **ctx.kwargs)
  File "C:\Users\wildc\AppData\Local\Programs\Python\Python38-32\lib\site-packages\discord\ext\commands\core.py", line 94, in wrapped
    raise CommandInvokeError(exc) from exc
discord.ext.commands.errors.CommandInvokeError: Command raised an exception: NameError: name '_file_' is not defined
INFO:discord.client:Received signal to terminate bot and event loop.
INFO:discord.client:Cleaning up tasks.
INFO:discord.client:Cleaning up after 1 tasks.
INFO:discord.client:All tasks finished cancelling.
INFO:discord.client:Closing the event loop.

C:\Users\wildc\Documents\GitHub\ShieldBot>bot.py
C:\Users\wildc\Documents\GitHub\ShieldBot
-----
INFO:discord.client:logging in using static token
INFO:discord.gateway:Shard ID None has sent the IDENTIFY payload.
INFO:discord.gateway:Shard ID None has connected to Gateway: ["gateway-prd-main-1g7b",{"micros":145215,"calls":["discord-sessions-prd-2-31",{"micros":138968,"calls":["start_session",{"micros":71062,"calls":["api-prd-main-2718",{"micros":68245,"calls":["get_user",{"micros":6879},"add_authorized_ip",{"micros":4040},"get_guilds",{"micros":3231},"coros_wait",{"micros":1}]}]},"guilds_connect",{"micros":9,"calls":[]},"presence_connect",{"micros":45361,"calls":[]}]}]}] (Session ID: a03043f206599c858d694a272b284e6d).
-----
Logged in as: ShieldBot <@754876371829784717>
-----
My current prefix is: .
-----
Commands Cog had been loaded
-----
Events Cog had been loaded
-----
INFO:discord.client:Received signal to terminate bot and event loop.
INFO:discord.client:Cleaning up tasks.
INFO:discord.client:Cleaning up after 1 tasks.
INFO:discord.client:All tasks finished cancelling.
INFO:discord.client:Closing the event loop.

C:\Users\wildc\Documents\GitHub\ShieldBot>